Workbook

Sheet Instructions
A1: RQ1 Accuracy Audit — Scoring Sheet Instructions
A3: This workbook has four data sheets:
A5: 1. Claim Audit — The main sheet. For each narrative, list every factual claim and score it.
A6: - Claim Types: Numerical (a specific number), Directional (trend up/down/stable),
A7: Entity (named category/column/period), Fabrication (claim with no basis in bundle), Hedging (language check)
A8: - Verdicts: Accurate (matches bundle exactly), Inaccurate (contradicts bundle),
A9: Fabricated (not in bundle at all), Partially Accurate (right direction but wrong number)
A10: - Evidence Bundle Reference: paste or describe the specific metric from the bundle that you checked against
A12: 2. Narrative Summary — One row per generated narrative. Tallies from the Claim Audit sheet.
A13: - Fill in the total/accurate/inaccurate counts after completing the claim audit
A14: - Accuracy Rate auto-calculates from the counts
A16: 3. Pipeline Success — One row per query. Tracks whether each pipeline stage succeeded.
... A30: 8. After all narratives are audited, fill in Summary Stats

Sheet Claim Audit
A1: Run ID | B1: Query | C1: Template Type | D1: Claim # | E1: Claim Text | F1: Claim Type | G1: Evidence Bundle Reference | H1: Verdict | I1: Notes
A2: run_01a | B2: What are the trends in waste collection? | C2: time_series | D2: 1 | E2: Residents Throw Away a Third Less Waste Than 15 Years Ago | F2: Numerical | G2: total_periods: 15, pct_change = 34.96 | H2: Accurate
A3: run_01a | B3: What are the trends in waste collection? | C3: time_series | D3: 2 | E3: Most households set out their bins every week, but the numbers reveal something surprising: we’re now tossing out much less than before. | F3: Numerical | G3: pct_change=34.96 | H3: Accurate | I3: First part is a generalization, could be categorized as fabrication
A4: run_01a | B4: What are the trends in waste collection? | C4: time_series | D4: 3 | E4: In Reykjavík, the amount of household waste per person has dropped by about a third since 1998—falling from 266 kilos a year to just 173 kilos by 2012. | F4: Numerical | G4: date_range: min=1998 max=2012 | trend[Kíló á íbúa]: direction=decreasing, first=266.0, last=173.0, pct_change=-34.96, peak=273.0 @ 2000, trough=173.0 | summary_stats[Kíló á íbúa]: mean=232.13, min=173.0, max=273.0, total=3482.0 | H4: Accurate
A5: run_01a | B5: What are the trends in waste collection? | C5: time_series | D5: 4 | E5: 35% less — waste per person since 1998 | F5: Numerical | G5: date_range: min=1998 max=2012 | H5: Accurate
A6: run_01a | B6: What are the trends in waste collection? | C6: time_series | D6: 5 | E6: Each person in Reykjavík is now throwing away about a third less than they did 15 years ago. | F6: Hedging | G6: total_periods: 15, pct_change = 34.96 | H6: Accurate
A7: run_01a | B7: What are the trends in waste collection? | C7: time_series | D7: 6 | E7: In the chart below, you'll see how waste collected per person crept up to a high of 273 kilos around the year 2000. | F7: Numerical | G7: trend[Kíló á íbúa]: direction=decreasing, first=266.0, last=173.0, pct_change=-34.96, peak=273.0 @ 2000, trough=173.0 | summary_stats[Kíló á íbúa]: mean=232.13, min=173.0, max=273.0, total=3482.0 | H7: Accurate
A8: run_01a | B8: What are the trends in waste collection? | C8: time_series | D8: 7 | E8: After that, there’s a steady and sharp decline right through to 2012. | F8: Numerical | G8: date_range: min=1998 max=2012, first=266.0, last=173.0, pct_change=-34.96, peak=273.0 | H8: Accurate
A9: run_01a | B9: What are the trends in waste collection? | C9: time_series | D9: 8 | E9: By the end of this period, the average resident is producing 37% less waste than at the peak. | F9: Numerical | G9: trend[Fjöldi sorpíláta]: direction=decreasing, first=47200.0, last=37311.0, pct_change=-20.95, peak=47900.0 @ 2004, trough=37288.0 | summary_stats[Fjöldi sorpíláta]: mean=42565.13, min=37288.0, max=47900.0, total=638477.0 | H9: Accurate
A10: run_01a | B10: What are the trends in waste collection? | C10: time_series | D10: 9 | E10: This is the most dramatic shift in the numbers. | F10: Interpretation | G10: No match | H10: Accurate
A11: run_01a | B11: What are the trends in waste collection? | C11: time_series | D11: 11 | E11: The number of bins went up until 2004, reaching a high point, but then fell by about a fifth over the next eight years. | F11: Numerical | G11: trend[Fjöldi sorpíláta]: direction=decreasing, first=47200.0, last=37311.0, pct_change=-20.95, peak=47900.0 @ 2004, trough=37288.0 | H11: Accurate
A12: run_01a | B12: What are the trends in waste collection? | C12: time_series | D12: 12 | E12: By 2012, crews were collecting from nearly 11,000 fewer bins than at the peak. | F12: Numerical | G12: date_range: min=1998 max=2012, first=47200.0, last=37311.0, | H12: Accurate
A13: run_01a | B13: What are the trends in waste collection? | C13: time_series | D13: 13 | E13: This fall matches the drop in waste per person and shows a real change in how much is being thrown away. | F13: Interpretation | G13: trend[Fjöldi sorpíláta]: direction=decreasing, first=47200.0, last=37311.0, pct_change=-20.95, peak=47900.0 @ 2004, trough=37288.0 | trend[Kíló á íbúa]: direction=decreasing, first=266.0, last=173.0, pct_change=-34.96, peak=273.0 @ 2000, trough=173.0 | H13: Accurate
A14: run_01a | B14: What are the trends in waste collection? | C14: time_series | D14: 14 | E14: Filling your bin less means less waste picked up, fewer trips for city trucks, and likely lower costs for everyone. | F14: Interpretation | G14: No match | H14: Accurate
A15: run_01a | B15: What are the trends in waste collection? | C15: time_series | D15: 15 | E15: Seeing our habits shift so much in just over a decade hints at big changes in what—and how much—we use and throw away. | F15: Interpretation | G15: No match | H15: Accurate
... A17: run_01a | B17: What are the trends in waste collection? | C17: time_series | D17: 17 | E17: This story covers waste collection in Reykjavík households from 1998 to 2012. | F17: Numerical | G17: date_range: min=1998 max=2012 | H17: Accurate
A18: run_01a | B18: What are the trends in waste collection? | C18: time_series | D18: 18 | E18: All numbers are citywide averages—your home's habits may differ. | F18: Interpretation | G18: No match | H18: Accurate | I18: Correct hedging language, good interpretation
A19: run_01a | B19: What are the trends in waste collection? | C19: time_series | D19: 19 | E19: The figures come from the city's Environment and Planning division, but licence details are not specified, and costs after 2012 aren't included. | F19: Data note | G19: date_range: min=1998 max=2012, no licence found | H19: Accurate
A20: run_01a | B20: What are the trends in waste collection? | C20: time_series | D20: 20 | E20: Finally, big changes in 2004 and 2005 may be due to policy shifts, so keep in mind that the trends shown reflect both resident behavior and city practices. | F20: Interpretation | G20: trend[Fjöldi sorpíláta]: direction=decreasing, first=47200.0, last=37311.0, pct_change=-20.95, peak=47900.0 @ 2004, trough=37288.0 | H20: Accurate
A21: run_01b | B21: What are the trends in waste collection? | C21: time_series | D21: 1 | E21: Residents Throw Away a Third Less Than 15 Years Ago | F21: Numerical | G21: total_periods: 15 | H21: Accurate
A22: run_01b | B22: What are the trends in waste collection? | C22: time_series | D22: 2 | E22: Living in Reykjavík means keeping an eye on the waste bins. | F22: Interpretation | G22: No match | H22: Fabricated
A23: run_01b | B23: What are the trends in waste collection? | C23: time_series | D23: 3 | E23: But fewer bins and less rubbish are filling up the streets these days. | F23: Interpretation | G23: date_range: min=1998 max=2012 | total_periods: 15 | trend[Kíló á íbúa]: direction=decreasing, first=266.0, last=173.0, pct_change=-34.96, peak=273.0 @ 2000, trough=173.0 | summary_stats[Kíló á íbúa]: mean=232.13, min=173.0, max=273.0, total=3482.0 | H23: Accurate
A24: run_01b | B24: What are the trends in waste collection? | C24: time_series | D24: 4 | E24: Over the past 15 years, the amount of household waste per person has dropped by about 35%, falling from 266 kg in 1998 to just 173 kg in 2012. | F24: Numerical | G24: date_range: min=1998 max=2012 | total_periods: 15 | trend[Kíló á íbúa]: direction=decreasing, first=266.0, last=173.0, pct_change=-34.96, peak=273.0 @ 2000, trough=173.0 | summary_stats[Kíló á íbúa]: mean=232.13, min=173.0, max=273.0, total=3482.0 | H24: Accurate
A25: run_01b | B25: What are the trends in waste collection? | C25: time_series | D25: 5 | E25: 35% — less waste per person | F25: Numerical | G25: pct_change=34.96 | H25: Accurate
A26: run_01b | B26: What are the trends in waste collection? | C26: time_series | D26: 6 | E26: Since 1998, the amount each resident throws away has dropped by about a third. | F26: Hedging | G26: date_range: min=1998 max=2012 | H26: Accurate
A27: run_01b | B27: What are the trends in waste collection? | C27: time_series | D27: 7 | E27: In the chart below, you’ll notice the number of waste bins across the city steadily rises to a peak in 2004 and then falls sharply. | F27: Numerical | G27: trend[Fjöldi sorpíláta]: direction=decreasing, first=47200.0, last=37311.0, pct_change=-20.95, peak=47900.0 @ 2004, trough=37288.0 | H27: Accurate
A28: run_01b | B28: What are the trends in waste collection? | C28: time_series | D28: 8 | E28: There were about 47,200 bins in 1998, peaking around 47,900 in 2004. | F28: Numerical | G28: date_range: min=1998 max=2012 | trend[Fjöldi sorpíláta]: direction=decreasing, first=47200.0, last=37311.0, pct_change=-20.95, peak=47900.0 @ 2004, trough=37288.0 | summary_stats[Fjöldi sorpíláta]: mean=42565.13, min=37288.0, max=47900.0, total=638477.0 | H28: Accurate
A29: run_01b | B29: What are the trends in waste collection? | C29: time_series | D29: 9 | E29: But after that, the number dropped by about a fifth, landing at just over 37,300 bins in 2012. | F29: Numerical | G29: date_range: min=1998 max=2012, , trough=37288.0 | H29: Accurate
A30: run_01b | B30: What are the trends in waste collection? | C30: time_series | D30: 10 | E30: This shows that not only are people throwing away less, but fewer bins are needed for the job. | F30: Interpretation | G30: date_range: min=1998 max=2012 | trend[Fjöldi sorpíláta]: direction=decreasing, first=47200.0, last=37311.0, pct_change=-20.95, peak=47900.0 @ 2004, trough=37288.0 | summary_stats[Fjöldi sorpíláta]: mean=42565.13, min=37288.0, max=47900.0, total=638477.0 | H30: Accurate
... A42: run_02a | B42: Compare the number of children on the kindergarten waiting list by district and age group | C42: environmental | D42: 1 | E42: Number of Young Children in Single-Parent Families Has Dropped Since 2002 | F42: Numerical | G42: date_range: min=2002 max=2014 | trend[Fjöldi barna 0-2 ára]: direction=decreasing, first=4212.0, last=3555.0, pct_change=-15.6, peak=4212.0 @ 2002, trough=3555.0 | trend[Fjöldi barna 7-12 ára]: direction=decreasing, first=8493.0, last=7434.0, pct_change=-12.47, peak=8493.0 @ 2002, trough=7365.0 | H42: Accurate
A43: run_02a | B43: Compare the number of children on the kindergarten waiting list by district and age group | C43: environmental | D43: 2 | E43: Single-parent families are a vital part of life for many in Reykjavík, shaping everything from schools to playgrounds. | F43: Interpretation | H43: Accurate
A44: run_02a | B44: Compare the number of children on the kindergarten waiting list by district and age group | C44: environmental | D44: 3 | E44: Over the past decade, there have been fewer young children living with single parents—especially among the youngest age groups. | F44: Directional | G44: trend[Fjöldi barna 3-5 ára].groups[1.1. Gamli vesturbærinn]: direction=decreasing, first=70.0, last=66.0, pct_change=-5.71 | trend[Fjöldi barna 3-5 ára].groups[1.2. Vesturbær syðri]: direction=decreasing, first=138.0, last=105.0, pct_change=-23.91 | trend[Fjöldi barna 3-5 ára].groups[11.1. Grunarhverfi]: direction=decreasing, first=12.0, last=9.0, pct_change=-25.0 | trend[Fjöldi barna 3-5 ára].groups[11.2 Kjalarnes]: direction=increasing, first=3.0, last=5.0, pct_change=66.67 | trend[Fjöldi barna 3-5 ára].groups[2.1. Austurbær]: direction=increasing, first=98.0, last=101.0, pct_change=3.06 | trend[Fjöldi barna 3-5 ára].groups[2.2. Norðumýri]: direction=decreasing, first=75.0, last=70.0, pct_change=-6.67 | trend[Fjöldi barna 3-5 ára].groups[2.3. Hlíðar]: direction=decreasing, first=60.0, last=56.0, pct_change=-6.67 | trend[Fjöldi barna 3-5 ára].groups[20.1. Óstaðsettir í Reykjavík]: direction=decreasing, first=3.0, last=1.0, pct_change=-66.67 | trend[Fjöldi barna 3-5 ára].groups[3.1. Laugarnes]: direction=decreasing, first=43.0, last=38.0, pct_change=-11.63 | trend[Fjöldi barna 3-5 ára].groups[3.2.Laugarás]: direction=decreasing, first=68.0, last=65.0, pct_change=-4.41 | H44: Accurate
A45: run_02a | B45: Compare the number of children on the kindergarten waiting list by district and age group | C45: environmental | D45: 4 | E45: For instance, the number of 0–2 year olds in these families dropped by about 16% since 2002. | F45: Numerical | G45: Fjöldi barna 0-2 ára is decreasing (-15.6% change from 4212.0 to 3555.0) | H45: Accurate
A46: run_02a | B46: Compare the number of children on the kindergarten waiting list by district and age group | C46: environmental | D46: 5 | E46: 16% — fewer 0–2 year olds in 2014 vs. 2002 | F46: Numerical | G46: Fjöldi barna 0-2 ára is decreasing (-15.6% change from 4212.0 to 3555.0) | H46: Accurate
A47: run_02a | B47: Compare the number of children on the kindergarten waiting list by district and age group | C47: environmental | D47: 6 | E47: This is the steepest drop among all age groups of children in single-parent families. | F47: Numerical | G47: Key findings Fjöldi barna 3-5 ára is decreasing (-4.5% change from 4449.0 to 4251.0) Fjöldi barna 3-5 ára peak: 4689.0 at 2004 Fjöldi foreldra is decreasing (-2.1% change from 16563.0 to 16215.0) Fjöldi foreldra peak: 16905.0 at 2004 Fjöldi barna, alls is decreasing (-3.9% change from 24483.0 to 23538.0) Fjöldi barna, alls peak: 25092.0 at 2004 Fjöldi barna 0-2 ára is decreasing (-15.6% change from 4212.0 to 3555.0) Fjöldi barna 0-2 ára peaked at 4212.0 (2002) then dropped 16% to 3555.0 Fjöldi barna 6 ára is increasing (+1.7% change from 1398.0 to 1422.0) Fjöldi barna 6 ára peak: 1509.0 at 2005 Fjöldi barna 7-12 ára is decreasing (-12.5% change from 8493.0 to 7434.0) Fjöldi barna 7-12 ára peak: 8493.0 at 2002 Fjöldi barna 13-16 ára is increasing (+16.7% change from 4653.0 to 5430.0) Fjöldi barna 13-16 ára peak: 5769.0 at 2006 Fjöldi barna 17 ára is increasing (+13.2% change from 1278.0 to 1446.0) Fjöldi barna 17 ára peak: 1554.0 at 2011 Data covers 2002 to 2014 (13 periods) pm2_5 exceeded WHO guideline (5 µg/m³) in 90.7% of readings | H47: Accurate
A48: run_02a | B48: Compare the number of children on the kindergarten waiting list by district and age group | C48: environmental | D48: 7 | E48: In the chart below, you’ll see how the number of very young children (ages 0–2) in single-parent families started high in 2002 but then fell sharply. | F48: Numerical | G48: date_range: min=2002 max=2014 | trend[Fjöldi barna 3-5 ára]: direction=decreasing, first=4449.0, last=4251.0, pct_change=-4.45, peak=4689.0 @ 2004, trough=3540.0 | trend[Fjöldi barna 3-5 ára].groups[1.1. Gamli vesturbærinn]: direction=decreasing, first=70.0, last=66.0, pct_change=-5.71 | trend[Fjöldi barna 3-5 ára].groups[1.2. Vesturbær syðri]: direction=decreasing, first=138.0, last=105.0, pct_change=-23.91 | trend[Fjöldi barna 3-5 ára].groups[11.1. Grunarhverfi]: direction=decreasing, first=12.0, last=9.0, pct_change=-25.0 | trend[Fjöldi barna 3-5 ára].groups[11.2 Kjalarnes]: direction=increasing, first=3.0, last=5.0, pct_change=66.67 | trend[Fjöldi barna 3-5 ára].groups[2.1. Austurbær]: direction=increasing, first=98.0, last=101.0, pct_change=3.06 | trend[Fjöldi barna 3-5 ára].groups[2.2. Norðumýri]: direction=decreasing, first=75.0, last=70.0, pct_change=-6.67 | trend[Fjöldi barna 3-5 ára].groups[2.3. Hlíðar]: direction=decreasing, first=60.0, last=56.0, pct_change=-6.67 | trend[Fjöldi barna 3-5 ára].groups[20.1. Óstaðsettir í Reykjavík]: direction=decreasing, first=3.0, last=1.0, pct_change=-66.67 | trend[Fjöldi barna 3-5 ára].groups[3.1. Laugarnes]: direction=decreasing, first=43.0, last=38.0, pct_change=-11.63 | trend[Fjöldi barna 3-5 ára].groups[3.2.Laugarás]: direction=decreasing, first=68.0, last=65.0, pct_change=-4.41 | … | H48: Accurate
A49: run_02a | B49: Compare the number of children on the kindergarten waiting list by district and age group | C49: environmental | D49: 8 | E49: The numbers peaked early and then declined steadily for more than a decade—about one in six fewer infants and toddlers by 2014. | F49: Numerical | G49: date_range: min=2002 max=2014 | trend[Fjöldi barna 3-5 ára]: direction=decreasing, first=4449.0, last=4251.0, pct_change=-4.45, peak=4689.0 @ 2004, trough=3540.0 | trend[Fjöldi barna 3-5 ára].groups[1.1. Gamli vesturbærinn]: direction=decreasing, first=70.0, last=66.0, pct_change=-5.71 | trend[Fjöldi barna 3-5 ára].groups[1.2. Vesturbær syðri]: direction=decreasing, first=138.0, last=105.0, pct_change=-23.91 | trend[Fjöldi barna 3-5 ára].groups[11.1. Grunarhverfi]: direction=decreasing, first=12.0, last=9.0, pct_change=-25.0 | trend[Fjöldi barna 3-5 ára].groups[11.2 Kjalarnes]: direction=increasing, first=3.0, last=5.0, pct_change=66.67 | trend[Fjöldi barna 3-5 ára].groups[2.1. Austurbær]: direction=increasing, first=98.0, last=101.0, pct_change=3.06 | trend[Fjöldi barna 3-5 ára].groups[2.2. Norðumýri]: direction=decreasing, first=75.0, last=70.0, pct_change=-6.67 | trend[Fjöldi barna 3-5 ára].groups[2.3. Hlíðar]: direction=decreasing, first=60.0, last=56.0, pct_change=-6.67 | trend[Fjöldi barna 3-5 ára].groups[20.1. Óstaðsettir í Reykjavík]: direction=decreasing, first=3.0, last=1.0, pct_change=-66.67 | trend[Fjöldi barna 3-5 ára].groups[3.1. Laugarnes]: direction=decreasing, first=43.0, last=38.0, pct_change=-11.63 | trend[Fjöldi barna 3-5 ára].groups[3.2.Laugarás]: direction=decreasing, first=68.0, last=65.0, pct_change=-4.41 | … | H49: Accurate
A50: run_02a | B50: Compare the number of children on the kindergarten waiting list by district and age group | C50: environmental | D50: 9 | E50: This points to smaller numbers of the youngest children in these families over time. | G50: date_range: min=2002 max=2014 | trend[Fjöldi barna 3-5 ára]: direction=decreasing, first=4449.0, last=4251.0, pct_change=-4.45, peak=4689.0 @ 2004, trough=3540.0 | trend[Fjöldi barna 3-5 ára].groups[1.1. Gamli vesturbærinn]: direction=decreasing, first=70.0, last=66.0, pct_change=-5.71 | trend[Fjöldi barna 3-5 ára].groups[1.2. Vesturbær syðri]: direction=decreasing, first=138.0, last=105.0, pct_change=-23.91 | trend[Fjöldi barna 3-5 ára].groups[11.1. Grunarhverfi]: direction=decreasing, first=12.0, last=9.0, pct_change=-25.0 | trend[Fjöldi barna 3-5 ára].groups[11.2 Kjalarnes]: direction=increasing, first=3.0, last=5.0, pct_change=66.67 | trend[Fjöldi barna 3-5 ára].groups[2.1. Austurbær]: direction=increasing, first=98.0, last=101.0, pct_change=3.06 | trend[Fjöldi barna 3-5 ára].groups[2.2. Norðumýri]: direction=decreasing, first=75.0, last=70.0, pct_change=-6.67 | trend[Fjöldi barna 3-5 ára].groups[2.3. Hlíðar]: direction=decreasing, first=60.0, last=56.0, pct_change=-6.67 | trend[Fjöldi barna 3-5 ára].groups[20.1. Óstaðsettir í Reykjavík]: direction=decreasing, first=3.0, last=1.0, pct_change=-66.67 | trend[Fjöldi barna 3-5 ára].groups[3.1. Laugarnes]: direction=decreasing, first=43.0, last=38.0, pct_change=-11.63 | trend[Fjöldi barna 3-5 ára].groups[3.2.Laugarás]: direction=decreasing, first=68.0, last=65.0, pct_change=-4.41 | … | H50: Accurate
A51: run_02a | B51: Compare the number of children on the kindergarten waiting list by district and age group | C51: environmental | D51: 10 | E51: It compares different parts of Reykjavík and shows big gaps between areas. | F51: Entity | G51: trend[Fjöldi barna 3-5 ára].groups[20.1. Óstaðsettir í Reykjavík]: direction=decreasing, first=3.0, last=1.0, pct_change=-66.67 | trend[Fjöldi barna 3-5 ára].groups[Reykjavík, alls]: direction=decreasing, first=1483.0, last=1417.0, pct_change=-4.45 | latest_period_comparison[Fjöldi barna 3-5 ára] 20.1. Óstaðsettir í Reykjavík=1.0 | latest_period_comparison[Fjöldi barna 3-5 ára] Reykjavík, alls=1417.0 | trend[Fjöldi foreldra].groups[20.1. Óstaðsettir í Reykjavík]: direction=decreasing, first=11.0, last=4.0, pct_change=-63.64 | trend[Fjöldi foreldra].groups[Reykjavík, alls]: direction=decreasing, first=5521.0, last=5405.0, pct_change=-2.1 | latest_period_comparison[Fjöldi foreldra] 20.1. Óstaðsettir í Reykjavík=4.0 | latest_period_comparison[Fjöldi foreldra] Reykjavík, alls=5405.0 | trend[Fjöldi barna, alls].groups[20.1. Óstaðsettir í Reykjavík]: direction=decreasing, first=17.0, last=5.0, pct_change=-70.59 | trend[Fjöldi barna, alls].groups[Reykjavík, alls]: direction=decreasing, first=8161.0, last=7846.0, pct_change=-3.86 | H51: Accurate
A52: run_02a | B52: Compare the number of children on the kindergarten waiting list by district and age group | C52: environmental | D52: 11 | E52: Some districts have many more children in single-parent families than others. | F52: Numerical | G52: trend[Fjöldi barna 3-5 ára].groups[20.1. Óstaðsettir í Reykjavík]: direction=decreasing, first=3.0, last=1.0, pct_change=-66.67 | trend[Fjöldi barna 3-5 ára].groups[Reykjavík, alls]: direction=decreasing, first=1483.0, last=1417.0, pct_change=-4.45 | latest_period_comparison[Fjöldi barna 3-5 ára] 20.1. Óstaðsettir í Reykjavík=1.0 | latest_period_comparison[Fjöldi barna 3-5 ára] Reykjavík, alls=1417.0 | trend[Fjöldi foreldra].groups[20.1. Óstaðsettir í Reykjavík]: direction=decreasing, first=11.0, last=4.0, pct_change=-63.64 | trend[Fjöldi foreldra].groups[Reykjavík, alls]: direction=decreasing, first=5521.0, last=5405.0, pct_change=-2.1 | latest_period_comparison[Fjöldi foreldra] 20.1. Óstaðsettir í Reykjavík=4.0 | latest_period_comparison[Fjöldi foreldra] Reykjavík, alls=5405.0 | trend[Fjöldi barna, alls].groups[20.1. Óstaðsettir í Reykjavík]: direction=decreasing, first=17.0, last=5.0, pct_change=-70.59 | trend[Fjöldi barna, alls].groups[Reykjavík, alls]: direction=decreasing, first=8161.0, last=7846.0, pct_change=-3.86 | H52: Accurate
...

Sheet Narrative Summary
A1: Run ID | B1: Query | C1: Template Type | D1: Run # | E1: Schema Valid? | F1: Retries Needed | G1: Total Claims | H1: Accurate | I1: Inaccurate | J1: Fabricated | K1: Accuracy Rate | L1: Hallucination Free? | M1: Hedging Compliant? | N1: Generation Time (s) | O1: Notes
A2: run_01a | B2: What are the trends in waste collection? | C2: time_series | D2: 1 | E2: Yes | F2: 0 | G2: =COUNTIF('Claim Audit'!$A:$A,A2) -> 19 | H2: =COUNTIFS('Claim Audit'!$A:$A,A2,'Claim Audit'!$H:$H,"Accurate") -> 19 | I2: =COUNTIFS('Claim Audit'!$A:$A,A2,'Claim Audit'!$H:$H,"Inaccurate") -> 0 | J2: =COUNTIFS('Claim Audit'!$A:$A,A2,'Claim Audit'!$H:$H,"Fabricated") -> 0 | K2: =IF(G2=0,"",H2/G2) -> 1 | L2: =IF(J2=0,"Yes","No") -> Yes | M2: =IF(COUNTIFS('Claim Audit'!$A:$A,A2,'Claim Audit'!$F:$F,"Hedging")=0,"N/A",IF(COUNTIFS('Claim Audit'!$A:$A,A2,'Claim Audit'!$F:$F,"Hedging",'Claim Audit'!$H:$H,"Accurate")=COUNTIFS('Claim Audit'!$A:$A,A2,'Claim Audit'!$F:$F,"Hedging"),"Yes","No")) -> Yes | N2: 10.06
A3: run_01b | B3: What are the trends in waste collection? | C3: time_series | D3: 2 | E3: Yes | F3: 0 | G3: =COUNTIF('Claim Audit'!$A:$A,A3) -> 21 | H3: =COUNTIFS('Claim Audit'!$A:$A,A3,'Claim Audit'!$H:$H,"Accurate") -> 20 | I3: =COUNTIFS('Claim Audit'!$A:$A,A3,'Claim Audit'!$H:$H,"Inaccurate") -> 0 | J3: =COUNTIFS('Claim Audit'!$A:$A,A3,'Claim Audit'!$H:$H,"Fabricated") -> 1 | K3: =IF(G3=0,"",H3/G3) -> 0.95238095 | L3: =IF(J3=0,"Yes","No") -> No | M3: Yes | N3: 8.02 | O3: Soft hallucation
A4: run_02a | B4: Compare the number of children on the kindergarten waiting list by district and age group | C4: environmental | D4: 3 | E4: Yes | F4: 0 | G4: =COUNTIF('Claim Audit'!$A:$A,A4) -> 22 | H4: =COUNTIFS('Claim Audit'!$A:$A,A4,'Claim Audit'!$H:$H,"Accurate") -> 22 | I4: =COUNTIFS('Claim Audit'!$A:$A,A4,'Claim Audit'!$H:$H,"Inaccurate") -> 0 | J4: =COUNTIFS('Claim Audit'!$A:$A,A4,'Claim Audit'!$H:$H,"Fabricated") -> 0 | K4: =IF(G4=0,"",H4/G4) -> 1 | L4: =IF(J4=0,"Yes","No") -> Yes | M4: Yes | N4: 12.17
A5: run_02b | B5: Compare the number of children on the kindergarten waiting list by district and age group | C5: categorical | D5: 4 | E5: Yes | F5: 0 | G5: =COUNTIF('Claim Audit'!$A:$A,A5) -> 19 | H5: =COUNTIFS('Claim Audit'!$A:$A,A5,'Claim Audit'!$H:$H,"Accurate") -> 18 | I5: =COUNTIFS('Claim Audit'!$A:$A,A5,'Claim Audit'!$H:$H,"Inaccurate") -> 0 | J5: =COUNTIFS('Claim Audit'!$A:$A,A5,'Claim Audit'!$H:$H,"Fabricated") -> 1 | K5: =IF(G5=0,"",H5/G5) -> 0.94736842 | L5: =IF(J5=0,"Yes","No") -> No | M5: Yes | N5: 9.46 | O5: Error due to insufficient/incorrect analytics input
A6: run_03a | B6: What are the air quality trends in the city? | C6: environmental | D6: 5 | E6: Yes | F6: 0 | G6: =COUNTIF('Claim Audit'!$A:$A,A6) -> 21 | H6: =COUNTIFS('Claim Audit'!$A:$A,A6,'Claim Audit'!$H:$H,"Accurate") -> 21 | I6: =COUNTIFS('Claim Audit'!$A:$A,A6,'Claim Audit'!$H:$H,"Inaccurate") -> 0 | J6: =COUNTIFS('Claim Audit'!$A:$A,A6,'Claim Audit'!$H:$H,"Fabricated") -> 0 | K6: =IF(G6=0,"",H6/G6) -> 1 | L6: =IF(J6=0,"Yes","No") -> Yes | M6: Yes | N6: 9.75
A7: run_03b | B7: What are the air quality trends in the city? | C7: environmental | D7: 6 | E7: Yes | F7: 0 | G7: =COUNTIF('Claim Audit'!$A:$A,A7) -> 21 | H7: =COUNTIFS('Claim Audit'!$A:$A,A7,'Claim Audit'!$H:$H,"Accurate") -> 20 | I7: =COUNTIFS('Claim Audit'!$A:$A,A7,'Claim Audit'!$H:$H,"Inaccurate") -> 0 | J7: =COUNTIFS('Claim Audit'!$A:$A,A7,'Claim Audit'!$H:$H,"Fabricated") -> 1 | K7: =IF(G7=0,"",H7/G7) -> 0.95238095 | L7: =IF(J7=0,"Yes","No") -> No | M7: Yes | N7: 10.44 | O7: Soft hallucation
A8: run_04a | B8: What is the population distribution across neighborhoods? | C8: environmental | D8: 7 | E8: No | G8: =COUNTIF('Claim Audit'!$A:$A,A8) -> 0 | H8: =COUNTIFS('Claim Audit'!$A:$A,A8,'Claim Audit'!$H:$H,"Accurate") -> 0 | I8: =COUNTIFS('Claim Audit'!$A:$A,A8,'Claim Audit'!$H:$H,"Inaccurate") -> 0 | J8: =COUNTIFS('Claim Audit'!$A:$A,A8,'Claim Audit'!$H:$H,"Fabricated") -> 0 | K8: =IF(G8=0,"",H8/G8) | O8: HTTP 200 with preview/fallback package (no LLM narrative). Generation time left blank so averages reflect successful LLM runs only.
A9: run_04b | B9: What is the population distribution across neighborhoods? | C9: environmental | D9: 8 | E9: No | G9: =COUNTIF('Claim Audit'!$A:$A,A9) -> 0 | H9: =COUNTIFS('Claim Audit'!$A:$A,A9,'Claim Audit'!$H:$H,"Accurate") -> 0 | I9: =COUNTIFS('Claim Audit'!$A:$A,A9,'Claim Audit'!$H:$H,"Inaccurate") -> 0 | J9: =COUNTIFS('Claim Audit'!$A:$A,A9,'Claim Audit'!$H:$H,"Fabricated") -> 0 | K9: =IF(G9=0,"",H9/G9) | O9: HTTP 200 with preview/fallback package (no LLM narrative). Generation time left blank so averages reflect successful LLM runs only.
A10: run_05a | B10: How has the city budget changed? | C10: time_series | D10: 9 | E10: Yes | F10: 0 | G10: =COUNTIF('Claim Audit'!$A:$A,A10) -> 21 | H10: =COUNTIFS('Claim Audit'!$A:$A,A10,'Claim Audit'!$H:$H,"Accurate") -> 19 | I10: =COUNTIFS('Claim Audit'!$A:$A,A10,'Claim Audit'!$H:$H,"Inaccurate") -> 0 | J10: =COUNTIFS('Claim Audit'!$A:$A,A10,'Claim Audit'!$H:$H,"Fabricated") -> 2 | K10: =IF(G10=0,"",H10/G10) -> 0.9047619 | L10: =IF(J10=0,"Yes","No") -> No | M10: No | N10: 10.67 | O10: Soft hallucation
A11: run_05b | B11: How has the city budget changed? | C11: time_series | D11: 10 | E11: Yes | F11: 0 | G11: =COUNTIF('Claim Audit'!$A:$A,A11) -> 19 | H11: =COUNTIFS('Claim Audit'!$A:$A,A11,'Claim Audit'!$H:$H,"Accurate") -> 19 | I11: =COUNTIFS('Claim Audit'!$A:$A,A11,'Claim Audit'!$H:$H,"Inaccurate") -> 0 | J11: =COUNTIFS('Claim Audit'!$A:$A,A11,'Claim Audit'!$H:$H,"Fabricated") -> 0 | K11: =IF(G11=0,"",H11/G11) -> 1 | L11: =IF(J11=0,"Yes","No") -> Yes | M11: No | N11: 8.44
A12: run_06a | B12: How many traffic accidents occurred these past years? | C12: time_series | D12: 11 | E12: Yes | F12: 0 | G12: =COUNTIF('Claim Audit'!$A:$A,A12) -> 20 | H12: =COUNTIFS('Claim Audit'!$A:$A,A12,'Claim Audit'!$H:$H,"Accurate") -> 19 | I12: =COUNTIFS('Claim Audit'!$A:$A,A12,'Claim Audit'!$H:$H,"Inaccurate") -> 0 | J12: =COUNTIFS('Claim Audit'!$A:$A,A12,'Claim Audit'!$H:$H,"Fabricated") -> 1 | K12: =IF(G12=0,"",H12/G12) -> 0.95 | L12: =IF(J12=0,"Yes","No") -> No | M12: Yes | N12: 10.01 | O12: Soft hallucation
A13: run_06b | B13: How many traffic accidents occurred these past years? | C13: time_series | D13: 12 | E13: Yes | F13: 0 | G13: =COUNTIF('Claim Audit'!$A:$A,A13) -> 22 | H13: =COUNTIFS('Claim Audit'!$A:$A,A13,'Claim Audit'!$H:$H,"Accurate") -> 22 | I13: =COUNTIFS('Claim Audit'!$A:$A,A13,'Claim Audit'!$H:$H,"Inaccurate") -> 0 | J13: =COUNTIFS('Claim Audit'!$A:$A,A13,'Claim Audit'!$H:$H,"Fabricated") -> 0 | K13: =IF(G13=0,"",H13/G13) -> 1 | L13: =IF(J13=0,"Yes","No") -> Yes | M13: Yes | N13: 9.21
A14: run_07a | B14: How many cruise ships have come to the city? | C14: time_series | D14: 13 | E14: Yes | F14: 0 | G14: =COUNTIF('Claim Audit'!$A:$A,A14) -> 23 | H14: =COUNTIFS('Claim Audit'!$A:$A,A14,'Claim Audit'!$H:$H,"Accurate") -> 23 | I14: =COUNTIFS('Claim Audit'!$A:$A,A14,'Claim Audit'!$H:$H,"Inaccurate") -> 0 | J14: =COUNTIFS('Claim Audit'!$A:$A,A14,'Claim Audit'!$H:$H,"Fabricated") -> 0 | K14: =IF(G14=0,"",H14/G14) -> 1 | L14: =IF(J14=0,"Yes","No") -> Yes | M14: Yes | N14: 10.45
A15: run_07b | B15: How many cruise ships have come to the city? | C15: time_series | D15: 14 | E15: Yes | F15: 0 | G15: =COUNTIF('Claim Audit'!$A:$A,A15) -> 26 | H15: =COUNTIFS('Claim Audit'!$A:$A,A15,'Claim Audit'!$H:$H,"Accurate") -> 26 | I15: =COUNTIFS('Claim Audit'!$A:$A,A15,'Claim Audit'!$H:$H,"Inaccurate") -> 0 | J15: =COUNTIFS('Claim Audit'!$A:$A,A15,'Claim Audit'!$H:$H,"Fabricated") -> 0 | K15: =IF(G15=0,"",H15/G15) -> 1 | L15: =IF(J15=0,"Yes","No") -> Yes | M15: Yes | N15: 11.26
A16: run_08a | B16: How has unemployment developed these past years? | C16: time_series | D16: 15 | E16: Yes | F16: 0 | G16: =COUNTIF('Claim Audit'!$A:$A,A16) -> 22 | H16: =COUNTIFS('Claim Audit'!$A:$A,A16,'Claim Audit'!$H:$H,"Accurate") -> 22 | I16: =COUNTIFS('Claim Audit'!$A:$A,A16,'Claim Audit'!$H:$H,"Inaccurate") -> 0 | J16: =COUNTIFS('Claim Audit'!$A:$A,A16,'Claim Audit'!$H:$H,"Fabricated") -> 0 | K16: =IF(G16=0,"",H16/G16) -> 1 | L16: =IF(J16=0,"Yes","No") -> Yes | M16: Yes | N16: 10.26
A17: run_08b | B17: How has unemployment developed these past years? | C17: time_series | D17: 16 | E17: Yes | F17: 0 | G17: =COUNTIF('Claim Audit'!$A:$A,A17) -> 22 | H17: =COUNTIFS('Claim Audit'!$A:$A,A17,'Claim Audit'!$H:$H,"Accurate") -> 22 | I17: =COUNTIFS('Claim Audit'!$A:$A,A17,'Claim Audit'!$H:$H,"Inaccurate") -> 0 | J17: =COUNTIFS('Claim Audit'!$A:$A,A17,'Claim Audit'!$H:$H,"Fabricated") -> 0 | K17: =IF(G17=0,"",H17/G17) -> 1 | L17: =IF(J17=0,"Yes","No") -> Yes | M17: Yes | N17: 9.72
A18: run_09a | B18: Which district has the most foreign citizens? | C18: time_series | D18: 17 | E18: Yes | F18: 0 | G18: =COUNTIF('Claim Audit'!$A:$A,A18) -> 21 | H18: =COUNTIFS('Claim Audit'!$A:$A,A18,'Claim Audit'!$H:$H,"Accurate") -> 21 | I18: =COUNTIFS('Claim Audit'!$A:$A,A18,'Claim Audit'!$H:$H,"Inaccurate") -> 0 | J18: =COUNTIFS('Claim Audit'!$A:$A,A18,'Claim Audit'!$H:$H,"Fabricated") -> 0 | K18: =IF(G18=0,"",H18/G18) -> 1 | L18: =IF(J18=0,"Yes","No") -> Yes | M18: Yes | N18: 9.75
A19: run_09b | B19: Which district has the most foreign citizens? | C19: time_series | D19: 18 | E19: Yes | F19: 0 | G19: =COUNTIF('Claim Audit'!$A:$A,A19) -> 18 | H19: =COUNTIFS('Claim Audit'!$A:$A,A19,'Claim Audit'!$H:$H,"Accurate") -> 18 | I19: =COUNTIFS('Claim Audit'!$A:$A,A19,'Claim Audit'!$H:$H,"Inaccurate") -> 0 | J19: =COUNTIFS('Claim Audit'!$A:$A,A19,'Claim Audit'!$H:$H,"Fabricated") -> 0 | K19: =IF(G19=0,"",H19/G19) -> 1 | L19: =IF(J19=0,"Yes","No") -> Yes | M19: Yes | N19: 7.95
A20: run_10a | B20: Compare population by age and gender | C20: environmental | D20: 19 | E20: No | G20: =COUNTIF('Claim Audit'!$A:$A,A20) -> 0 | H20: =COUNTIFS('Claim Audit'!$A:$A,A20,'Claim Audit'!$H:$H,"Accurate") -> 0 | I20: =COUNTIFS('Claim Audit'!$A:$A,A20,'Claim Audit'!$H:$H,"Inaccurate") -> 0 | J20: =COUNTIFS('Claim Audit'!$A:$A,A20,'Claim Audit'!$H:$H,"Fabricated") -> 0 | K20: =IF(G20=0,"",H20/G20) | O20: HTTP 200 with preview/fallback package (no LLM narrative). Generation time left blank so averages reflect successful LLM runs only.
A21: run_10b | B21: Compare population by age and gender | C21: environmental | D21: 20 | E21: No | G21: =COUNTIF('Claim Audit'!$A:$A,A21) -> 0 | H21: =COUNTIFS('Claim Audit'!$A:$A,A21,'Claim Audit'!$H:$H,"Accurate") -> 0 | I21: =COUNTIFS('Claim Audit'!$A:$A,A21,'Claim Audit'!$H:$H,"Inaccurate") -> 0 | J21: =COUNTIFS('Claim Audit'!$A:$A,A21,'Claim Audit'!$H:$H,"Fabricated") -> 0 | K21: =IF(G21=0,"",H21/G21) | O21: HTTP 200 with preview/fallback package (no LLM narrative). Generation time left blank so averages reflect successful LLM runs only.

Sheet Pipeline Success
A1: Run ID | B1: Query | C1: Dataset Selected | D1: Correct dataset? | E1: Ingestion OK? | F1: Profiling OK? | G1: Template Matched? | H1: Template Type | I1: Expected template type | J1: Correct template? | K1: Analytics OK? | L1: Charts Generated? | M1: All Charts rendered? | N1: Chart Types Appropriate? | O1: Narrative Generated? | P1: Pipeline Fully Successful? | Q1: Failure Point | R1: Notes
A2: run_01a | B2: What are the trends in waste collection? | C2: Sorphirða heimila í Reykjavík (sorphirda_heimila_i_reykjavik) | D2: Yes | E2: Yes | F2: Yes | G2: Yes | H2: time_series | I2: time_series | J2: Yes | K2: Yes | L2: Yes | M2: Yes | N2: Yes | O2: Yes | P2: Yes
A3: run_01b | B3: What are the trends in waste collection? | C3: Sorphirða heimila í Reykjavík (sorphirda_heimila_i_reykjavik) | D3: Yes | E3: Yes | F3: Yes | G3: Yes | H3: time_series | I3: time_series | J3: Yes | K3: Yes | L3: Yes | M3: Yes | N3: Yes | O3: Yes | P3: Yes
A4: run_02a | B4: Compare the number of children on the kindergarten waiting list by district and age group | C4: Einstæðir foreldrar í Reykjavík og börn þeirra eftir hverfum og aldri barna (einstaedir_foreldrar_i_reykjavik_og_born_theirra_eftir_hverfum_og_aldri) | D4: No | E4: Yes | F4: Yes | G4: Yes | H4: environmental | I4: time_series | J4: No | K4: Yes | L4: Yes | M4: Yes | N4: No | O4: Yes | P4: Yes | Q4: wrong template
A5: run_02b | B5: Compare the number of children on the kindergarten waiting list by district and age group | C5: Leikskólar í Reykjavík (leikskolar) | D5: Yes | E5: Yes | F5: Yes | G5: Yes | H5: categorical | I5: categorical | J5: Yes | K5: Yes | L5: Yes | M5: Yes | N5: Yes | O5: Yes | P5: Yes
A6: run_03a | B6: What are the air quality trends in the city? | C6: Loftmengun í Reykjavík, mælingar frá Grensásvegi (loftmengun_i_reykjavik_maelingar_fra_grensasvegi) | D6: Yes | E6: Yes | F6: Yes | G6: Yes | H6: environmental | I6: environmental | J6: Yes | K6: Yes | L6: Yes | M6: No | N6: No | O6: Yes | P6: Yes | Q6: heatmap had error
A7: run_03b | B7: What are the air quality trends in the city? | C7: Loftmengun í Reykjavík, mælingar frá Grensásvegi (loftmengun_i_reykjavik_maelingar_fra_grensasvegi) | D7: Yes | E7: Yes | F7: Yes | G7: Yes | H7: environmental | I7: environmental | J7: Yes | K7: Yes | L7: Yes | M7: No | N7: No | O7: Yes | P7: Yes | Q7: heatmap had error
A8: run_04a | B8: What is the population distribution across neighborhoods? | C8: Mannfjöldi í Reykjavík eftir hverfum, kyni og aldri (mannfjoldi_i_reykjavik_eftir_hverfum_kyni_og_aldri) | D8: Yes | E8: Yes | F8: Yes | G8: Yes | H8: environmental | I8: demographic | J8: No | K8: Yes | L8: Yes | M8: Yes | N8: Yes | O8: No | P8: No | Q8: LLM narrative not produced (preview / template analysis only) | R8: wrong template
A9: run_04b | B9: What is the population distribution across neighborhoods? | C9: Mannfjöldi í Reykjavík eftir hverfum, kyni og aldri (mannfjoldi_i_reykjavik_eftir_hverfum_kyni_og_aldri) | D9: Yes | E9: Yes | F9: Yes | G9: Yes | H9: environmental | I9: demographic | J9: No | K9: Yes | L9: Yes | M9: Yes | N9: Yes | O9: No | P9: No | Q9: LLM narrative not produced (preview / template analysis only) | R9: wrong template
A10: run_05a | B10: How has the city budget changed? | C10: Sjóðstreymi (sjodstreymi) | D10: Yes | E10: Yes | F10: Yes | G10: Yes | H10: time_series | I10: budget | J10: No | K10: Yes | L10: Yes | M10: Yes | N10: Yes | O10: Yes | P10: Yes
A11: run_05b | B11: How has the city budget changed? | C11: Sjóðstreymi (sjodstreymi) | D11: Yes | E11: Yes | F11: Yes | G11: Yes | H11: time_series | I11: budget | J11: No | K11: Yes | L11: Yes | M11: Yes | N11: Yes | O11: Yes | P11: Yes
A12: run_06a | B12: How many traffic accidents occurred these past years? | C12: Umferðarslys og árekstrar í Reykjavík (umferdarslys_og_arekstrar_i_reykjavik) | D12: Yes | E12: Yes | F12: Yes | G12: Yes | H12: time_series | I12: time_series | J12: Yes | K12: Yes | L12: Yes | M12: Yes | N12: Yes | O12: Yes | P12: Yes
A13: run_06b | B13: How many traffic accidents occurred these past years? | C13: Umferðarslys og árekstrar í Reykjavík (umferdarslys_og_arekstrar_i_reykjavik) | D13: Yes | E13: Yes | F13: Yes | G13: Yes | H13: time_series | I13: time_series | J13: Yes | K13: Yes | L13: Yes | M13: Yes | N13: Yes | O13: Yes | P13: Yes
A14: run_07a | B14: How many cruise ships have come to the city? | C14: Þjóðerni og fjöldi farþega skemmtiferðaskipa sem fara um hafnir Faxaflóahafna (thjoderni_og_fjoldi_farthega_skemmtiferdaskipa_sem_fara_um_hafnir_faxafloahafna) | D14: Yes | E14: Yes | F14: Yes | G14: Yes | H14: time_series | I14: time_series | J14: Yes | K14: Yes | L14: Yes | M14: Yes | N14: Yes | O14: Yes | P14: Yes
A15: run_07b | B15: How many cruise ships have come to the city? | C15: Þjóðerni og fjöldi farþega skemmtiferðaskipa sem fara um hafnir Faxaflóahafna (thjoderni_og_fjoldi_farthega_skemmtiferdaskipa_sem_fara_um_hafnir_faxafloahafna) | D15: Yes | E15: Yes | F15: Yes | G15: Yes | H15: time_series | I15: time_series | J15: Yes | K15: Yes | L15: Yes | M15: Yes | N15: Yes | O15: Yes | P15: Yes
A16: run_08a | B16: How has unemployment developed these past years? | C16: Atvinnuleysi í Reykjavík eftir mánuðum og lengd atvinnuleysis (atvinnuleysi_i_reykjavik_eftir_manudum_og_lengd_atvinnuleysis) | D16: Yes | E16: Yes | F16: Yes | G16: Yes | H16: time_series | I16: time_series | J16: Yes | K16: Yes | L16: Yes | M16: Yes | N16: No | O16: Yes | P16: Yes | Q16: plotting incompatible things together
A17: run_08b | B17: How has unemployment developed these past years? | C17: Atvinnuleysi í Reykjavík eftir mánuðum og lengd atvinnuleysis (atvinnuleysi_i_reykjavik_eftir_manudum_og_lengd_atvinnuleysis) | D17: Yes | E17: Yes | F17: Yes | G17: Yes | H17: time_series | I17: time_series | J17: Yes | K17: Yes | L17: Yes | M17: Yes | N17: No | O17: Yes | P17: Yes | Q17: plotting incompatible things together
A18: run_09a | B18: Which district has the most foreign citizens? | C18: Erlendir ríkisborgarar í Reykjaví­k eftir hverfum (erlendir_rikisborgarar_i_reykjavik_eftir_hverfum) | D18: Yes | E18: Yes | F18: Yes | G18: Yes | H18: time_series | I18: time_series | J18: Yes | K18: Yes | L18: Yes | M18: Yes | N18: Yes | O18: Yes | P18: Yes
A19: run_09b | B19: Which district has the most foreign citizens? | C19: Upplifað öryggi (upplifad_oryggi) | D19: No | E19: Yes | F19: Yes | G19: Yes | H19: time_series | I19: time_series | J19: Yes | K19: Yes | L19: Yes | M19: Yes | N19: Yes | O19: Yes | P19: Yes
A20: run_10a | B20: Compare population by age and gender | C20: Mannfjöldi í Reykjavík eftir hverfum, kyni og aldri (mannfjoldi_i_reykjavik_eftir_hverfum_kyni_og_aldri) | D20: Yes | E20: Yes | F20: Yes | G20: Yes | H20: environmental | I20: demographic | J20: No | K20: Yes | L20: Yes | M20: No | N20: No | O20: No | P20: No | Q20: LLM narrative not produced (preview / template analysis only) | R20: wrong template
A21: run_10b | B21: Compare population by age and gender | C21: Mannfjöldi í Reykjavík eftir hverfum, kyni og aldri (mannfjoldi_i_reykjavik_eftir_hverfum_kyni_og_aldri) | D21: Yes | E21: Yes | F21: Yes | G21: Yes | H21: environmental | I21: demographic | J21: No | K21: Yes | L21: Yes | M21: No | N21: No | O21: No | P21: No | Q21: LLM narrative not produced (preview / template analysis only) | R21: wrong template

Sheet Summary Stats
A1: Metric | B1: Value | C1: Notes
A2: NARRATIVE ACCURACY
A3: Total narratives evaluated | B3: =COUNTA('Narrative Summary'!A:A)-1 -> 20
A4: Total claims audited | B4: =COUNTA('Claim Audit'!A:A)-1 -> 337
A5: Numerical claims accurate | B5: =COUNTIFS('Claim Audit'!$F:$F,"Numerical",'Claim Audit'!$H:$H,"Accurate")/COUNTIF('Claim Audit'!$F:$F,"Numerical") -> 1
A6: Directional claims accurate | B6: =COUNTIFS('Claim Audit'!$F:$F,"Directional",'Claim Audit'!$H:$H,"Accurate")/COUNTIF('Claim Audit'!$F:$F,"Directional") -> 1
A7: Interpretation claims accurate | B7: =COUNTIFS('Claim Audit'!$F:$F,"Interpretation",'Claim Audit'!$H:$H,"Accurate")/COUNTIF('Claim Audit'!$F:$F,"Interpretation") -> 0.93023256
A8: Entity claims accurate | B8: =COUNTIFS('Claim Audit'!$F:$F,"Entity",'Claim Audit'!$H:$H,"Accurate")/COUNTIF('Claim Audit'!$F:$F,"Entity") -> 1
A9: Narratives with zero fabrications | B9: =COUNTIF('Narrative Summary'!J:J,0)-4 -> 11 | C9: all fabrications soft
A10: Overall claim accuracy rate | B10: =COUNTIF('Claim Audit'!H:H,"Accurate")/B4 -> 0.98219585
A11: Hedging compliance rate | B11: =COUNTIFS('Claim Audit'!F:F,"Hedging",'Claim Audit'!H:H,"Accurate")/COUNTIF('Claim Audit'!F:F,"Hedging") -> 1
A13: STRUCTURAL VALIDITY
A14: Schema valid on first attempt | B14: =COUNTIFS('Narrative Summary'!E:E,"Yes",'Narrative Summary'!F:F,0) -> 16
A15: Schema valid after retry | B15: =COUNTIFS('Narrative Summary'!E:E,"Yes",'Narrative Summary'!F:F,">0") -> 0 | C15: No retries
A16: Average retries needed | B16: =AVERAGEIF('Narrative Summary'!E:E,"Yes",'Narrative Summary'!F:F) -> 0
A18: PIPELINE SUCCESS
A19: Total queries tested | B19: {=COUNTA(_xlfn.UNIQUE(_xlfn._xlws.FILTER('Pipeline Success'!B2:B1000,'Pipeline Success'!B2:B1000<>"")))} -> 10
A20: Successful ingestions | B20: =COUNTIF('Pipeline Success'!E:E,"Yes") -> 20
A21: Successful template matches | B21: =COUNTIF('Pipeline Success'!F:F,"Yes") -> 20
A22: Successful analytics runs | B22: =COUNTIF('Pipeline Success'!K:K,"Yes") -> 20
A23: Successful chart generations | B23: =COUNTIF('Pipeline Success'!L:L,"Yes") -> 20
A24: Full pipeline success rate | B24: =COUNTIF('Pipeline Success'!P:P,"Yes")/B19 -> 1.6
A26: CONSISTENCY
A27: Queries run twice | B27: 10 | C27: all of them
A28: Queries with consistent main finding | B28: =12/16 -> 0.75
A29: Queries with consistent trend direction | B29: =16/16 -> 1
